Workbook

Sheet EJECUCION
H2: =SUBTOTAL(9,H4:H1001) -> 54794383 | J2: =SUBTOTAL(9,J4:J1001) -> 60728115 | K2: =SUBTOTAL(9,K4:K1001) -> 5933732
J3: PRESUPUESTO | K3: DIFERENCIA
J4: =IFERROR(VLOOKUP(G4,TD!B:C,2,0),0) -> 39400000 | K4: =J4-H4 -> 6287406
E5: =15000000-C5 -> 1186250 | J5: =IFERROR(VLOOKUP(G5,TD!B:C,2,0),0) -> 8044400 | K5: =J5-H5 -> 1137150
E6: =15000000-C6 -> 1521800 | J6: =IFERROR(VLOOKUP(G6,TD!B:C,2,0),0) -> 4680315 | K6: =J6-H6 -> 219315
E7: =15000000-C7 -> 3162216 | J7: =IFERROR(VLOOKUP(G7,TD!B:C,2,0),0) -> 4000000 | K7: =J7-H7 -> 0
J8: =IFERROR(VLOOKUP(G8,TD!B:C,2,0),0) -> 700000 | K8: =J8-H8 -> -694600
J9: =IFERROR(VLOOKUP(G9,TD!B:C,2,0),0) -> 600000 | K9: =J9-H9 -> -377000
J10: =IFERROR(VLOOKUP(G10,TD!B:C,2,0),0) -> 272000 | K10: =J10-H10 -> -639899
J11: =IFERROR(VLOOKUP(G11,TD!B:C,2,0),0) -> 750000 | K11: =J11-H11 -> 116000
J12: =IFERROR(VLOOKUP(G12,TD!B:C,2,0),0) -> 390000 | K12: =J12-H12 -> -55890
J13: =IFERROR(VLOOKUP(G13,TD!B:C,2,0),0) -> 500000 | K13: =J13-H13 -> 100000
J14: =IFERROR(VLOOKUP(G14,TD!B:C,2,0),0) -> 400000 | K14: =J14-H14 -> 100000
J15: =IFERROR(VLOOKUP(G15,TD!B:C,2,0),0) -> 315600 | K15: =J15-H15 -> 47600
J16: =IFERROR(VLOOKUP(G16,TD!B:C,2,0),0) -> 0 | K16: =J16-H16 -> -266000
J17: =IFERROR(VLOOKUP(G17,TD!B:C,2,0),0) -> 0 | K17: =J17-H17 -> -147850
J18: =IFERROR(VLOOKUP(G18,TD!B:C,2,0),0) -> 0 | K18: =J18-H18 -> -125000
J19: =IFERROR(VLOOKUP(G19,TD!B:C,2,0),0) -> 145800 | K19: =J19-H19 -> 35800
... J31: =IFERROR(VLOOKUP(G31,TD!B:C,2,0),0) -> 0 | K31: =J31-H31 -> 0

Sheet FORMULARIO
A1: Marca temporal | B1: TIPO | C1: Clase ingreso | D1: Columna 3 | E1: Tipo de gasto | F1: Fecha | G1: PERSONA REGISTRA GASTO | H1: Nombre | I1: Detalle | J1: Valor | K1: Forma de pago | L1: Subir soporte
A2: 46171.508 | B2: Inversión Inicial | E2: Arriendo | F2: 46170 | G2: DIANA PAOLA GARZON | H2: Arriendo inicial | I2: Valor de arriendo inicial | J2: 2000000 | K2: Transferencia (Tarjeta Debito, Nequi, Daviplata, Cuentas de ahorro)
A3: 46171.509 | B3: Inversión Inicial | E3: Computador | F3: 46170 | G3: MAURICIO GARZON | H3: Computador | I3: Compra de computador nuevo | J3: 400000 | K3: Transferencia (Tarjeta Debito, Nequi, Daviplata, Cuentas de ahorro)
A4: 46171.511 | B4: Inversión Inicial | E4: Sistema POS | F4: 46171 | G4: MAURICIO GARZON | H4: Creacion de dominio | I4: Creación de dominio de Be | J4: 45700 | K4: Transferencia (Tarjeta Debito, Nequi, Daviplata, Cuentas de ahorro) | L4: https://drive.google.com/open?id=1Pe-Fi_o_UFjPbPbIxoMPnZJBSe1y5oRH
A5: 46172.332 | B5: Gastos Variables de Operación | C5: Otros | E5: Comida | F5: 46172 | G5: ANTONIO RENTERIA | H5: Desayuno | I5: Desayuno | J5: 48000 | K5: Transferencia (Tarjeta Debito, Nequi, Daviplata, Cuentas de ahorro)
A6: 46172.417 | B6: Inversión Inicial | E6: Arreglos locativos | F6: 46171 | G6: MAURICIO GARZON | H6: Vidrios vitrinas entrada | I6: Pago la mitad de los vidrios de la vitrina | J6: 450000 | K6: Transferencia (Tarjeta Debito, Nequi, Daviplata, Cuentas de ahorro) | L6: https://drive.google.com/open?id=18Tfd1glS8YpXxHSYGLsg2fCpZQFm9sym
A7: 46172.418 | B7: Inversión Inicial | E7: Legalización | F7: 46171 | G7: YENI GARZON | H7: Matrícula Mercantil (Cámara de Comercio) | I7: Cámara de comercio Chapinero | J7: 65400 | K7: Transferencia (Tarjeta Debito, Nequi, Daviplata, Cuentas de ahorro)
A8: 46172.419 | B8: Inversión Inicial | E8: Legalización | F8: 46171 | G8: YENI GARZON | H8: Matrícula Mercantil (Cámara de Comercio) | I8: Certificado CCB Chapinero | J8: 6100 | K8: Transferencia (Tarjeta Debito, Nequi, Daviplata, Cuentas de ahorro)
A9: 46172.42 | B9: Inversión Inicial | E9: Comida | F9: 46172 | G9: DIANA PAOLA GARZON | H9: Desayuno | I9: Desayuno de Yeni y diana | J9: 29000 | K9: Efectivo
A10: 46172.423 | B10: Inversión Inicial | E10: Legalización | F10: 46172 | G10: YENI GARZON | H10: Matrícula Mercantil (Cámara de Comercio) | I10: Impresión contrato de arriendo | J10: 4800 | K10: Efectivo | N10: inversion inicial | O10: =RESUMEN!C19*4 -> 59588115
A11: 46172.793 | B11: Inversión Inicial | E11: Legalización | F11: 46172 | G11: DIANA PAOLA GARZON | H11: Matrícula Mercantil (Cámara de Comercio) | I11: Pago de autenticación | J11: 28500 | K11: Efectivo | N11: saldo por ejecutar | O11: =O10-O9 -> 4793732
A12: 46172.794 | B12: Inversión Inicial | E12: Comida | F12: 46172 | G12: DIANA PAOLA GARZON | H12: Almuerzos | I12: Almuerzos de todos | J12: 107000 | K12: Efectivo
A13: 46172.796 | B13: Inversión Inicial | E13: Movilidad | F13: 46172 | G13: DIANA PAOLA GARZON | H13: Parqueadero | I13: Parqueadero carro tio | J13: 21000 | K13: Efectivo
A14: 46172.797 | B14: Inversión Inicial | E14: Arriendo | F14: 46172 | G14: DIANA PAOLA GARZON | H14: Arriendo inicial | I14: Pago de arriendo y depósito 50% | J14: 2000000 | K14: Transferencia (Tarjeta Debito, Nequi, Daviplata, Cuentas de ahorro)
A15: 46172.805 | B15: Inversión Inicial | E15: Camaras | F15: 46172 | G15: DIANA PAOLA GARZON | H15: Camaras de seguridad | I15: Camaras de seguridad | J15: 634000 | K15: Transferencia (Tarjeta Debito, Nequi, Daviplata, Cuentas de ahorro)
A16: 46174.428 | B16: Gastos Variables de Operación | C16: Otros | E16: Gasolina | F16: 46172 | G16: ANTONIO RENTERIA | H16: Gasolina Carro | I16: Gasolina de transporte para las compras | J16: 30000 | K16: Efectivo
A17: 46174.43 | B17: Gastos Variables de Operación | C17: Otros | E17: Movilidad | F17: 46172 | G17: ANTONIO RENTERIA | H17: Parqueadero Carro | I17: Parqueadero del carro para las compras iniciales | J17: 25000 | K17: Efectivo
A18: 46174.596 | B18: Inversión Inicial | E18: Arreglos locativos | F18: 46174 | G18: MAURICIO GARZON | H18: Decoracion, Pintura, Vestier en Drywall | I18: Pago de adecuaciones de infraestructura | J18: 1055000 | K18: Transferencia (Tarjeta Debito, Nequi, Daviplata, Cuentas de ahorro) | L18: https://drive.google.com/open?id=1EsJ-NhcYdHfpSVqCXea9LeKCY3UJ10of
A19: 46174.634 | B19: Inversión Inicial | E19: Maniquies | F19: 46172 | G19: ANTONIO RENTERIA | H19: Cremallera para Flauta, Flautas para Exhibicion, Ganchera tripode, Ganchos de madera, Maniquies cuerpo Completo, Maniquies medio cuerpo, Cortina Negra | I19: 2 barra u de 120, 3 barra sencilla de 120, 4 barra de 120 con malla, 40 flautas para barra, 6 Parales de 3 MTS, 200 gancho pinza, 400 gancho cromo, 1 silla de 2 puesto, 1 burro cascada, 2 hombre, 2 dama, 1 niño 10 blanco, 9 rieles, 3 cortinas negras, 14 barra sencilla de 150, 8 barra u de 150, 1 tabla de 150, 1 burro sencillo negro, 1 la de 6 puestos, 1 palo Chino | J19: 4406000 | K19: Efectivo
A20: 46174.635 | B20: Inversión Inicial | E20: Maniquies | F20: 46172 | G20: YENI GARZON | H20: Mostrador | I20: Cachucheras | J20: 55000 | K20: Transferencia (Tarjeta Debito, Nequi, Daviplata, Cuentas de ahorro)
A21: 46174.638 | B21: Inversión Inicial | E21: Mercancia | F21: 46172 | G21: MAURICIO GARZON | H21: Mercancia | I21: Camisetas Colombia, España y Portugal 2 | J21: 1352000 | K21: Tarjeta de Credito
A22: 46174.641 | B22: Inversión Inicial | E22: Iluminacion | F22: 46172 | G22: MAURICIO GARZON | H22: Iluminacion interna y externa | I22: 40 spot de 20 w, 20 riel de 1 MTS, 3 bombillas para Vestier, 2 reflectores, 15 MTS duplex, 4 MTS luz neón | J22: 977000 | K22: Tarjeta de Credito
A23: 46174.643 | B23: Inversión Inicial | E23: Arreglos locativos | F23: 46173 | G23: YENI GARZON | H23: Pintura | I23: Aerosol y tornillos | J23: 52300 | K23: Efectivo
A24: 46174.644 | B24: Inversión Inicial | E24: Arreglos locativos | F24: 46174 | G24: MAURICIO GARZON | H24: Pintura | I24: Vinilo amarillo | J24: 13000 | K24: Efectivo
A25: 46176.162 | B25: Inversión Inicial | E25: Insumos | F25: 46175 | G25: YENI GARZON | H25: Implementos de aseo | I25: Escoba, recogedor | J25: 15400 | K25: Efectivo
A26: 46176.164 | B26: Inversión Inicial | E26: Arreglos locativos | F26: 46175 | G26: MAURICIO GARZON | H26: Decoracion | I26: Varillas, brocas tornillos | J26: 97450 | K26: Efectivo
A27: 46176.166 | B27: Inversión Inicial | E27: Arreglos locativos | F27: 46175 | G27: MAURICIO GARZON | H27: Decoracion | I27: Canales y amarres | J27: 18100 | K27: Efectivo
A28: 46176.168 | B28: Inversión Inicial | E28: Arreglos locativos | F28: 46175 | G28: MAURICIO GARZON | H28: Decoracion | I28: Parales y cinta | J28: 29800 | K28: Efectivo | P28: =O33-O28 -> 5200
A29: 46176.17 | B29: Inversión Inicial | E29: Insumos | F29: 46175 | G29: YENI GARZON | H29: Implementos de aseo | I29: Jabón rey, vasos, gaseosa | J29: 14400 | K29: Efectivo
A30: 46176.171 | B30: Inversión Inicial | E30: Arreglos locativos | F30: 46175 | G30: YENI GARZON | H30: Decoracion | I30: Pilas láser Anderson | J30: 4800 | K30: Efectivo
A31: 46176.172 | B31: Inversión Inicial | E31: Insumos | F31: 46175 | G31: YENI GARZON | H31: Implementos de aseo | I31: Aseo | J31: 37000 | K31: Efectivo
A32: 46176.774 | B32: Inversión Inicial | E32: Seguridad | F32: 46176 | G32: DIANA PAOLA GARZON | H32: Candados | I32: Candados comprados a la sra Berna | J32: 40000 | K32: Efectivo
A33: 46176.817 | B33: Inversión Inicial | E33: Seguridad | F33: 46176 | G33: DIANA PAOLA GARZON | H33: Candados | I33: Candados egret dorado | J33: 60000 | K33: Efectivo
A34: 46176.821 | B34: Inversión Inicial | E34: Mercancia | F34: 46176 | G34: DIANA PAOLA GARZON | H34: Inversión inicial | I34: Alimentación con Jonathan | J34: 50000 | K34: Efectivo
A35: 46177.795 | B35: Inversión Inicial | E35: Mercancia | F35: 46177 | G35: ANTONIO RENTERIA | H35: Mercancia | I35: Pantalones de hombre | J35: 2090000 | K35: Transferencia (Tarjeta Debito, Nequi, Daviplata, Cuentas de ahorro)
A36: 46177.795 | B36: Inversión Inicial | E36: Mercancia | F36: 46177 | G36: ANTONIO RENTERIA | H36: Mercancia | I36: Pantalones sudadera | J36: 560000 | K36: Transferencia (Tarjeta Debito, Nequi, Daviplata, Cuentas de ahorro)
A37: 46177.796 | B37: Inversión Inicial | E37: Mercancia | F37: 46177 | G37: DIANA PAOLA GARZON | H37: Mercancia | I37: Blusas mujer | J37: 358000 | K37: Transferencia (Tarjeta Debito, Nequi, Daviplata, Cuentas de ahorro)
A38: 46177.799 | B38: Inversión Inicial | E38: Gasolina | F38: 46176 | G38: ANTONIO RENTERIA | H38: Gasolina | I38: Gasolina carro | J38: 25000 | K38: Transferencia (Tarjeta Debito, Nequi, Daviplata, Cuentas de ahorro)
A39: 46177.8 | B39: Inversión Inicial | E39: Movilidad | F39: 46176 | G39: DIANA PAOLA GARZON | H39: Parqueadero | I39: Parqueadero | J39: 70000 | K39: Efectivo
A40: 46177.801 | B40: Inversión Inicial | E40: Comida | F40: 46176 | G40: DIANA PAOLA GARZON | H40: Desayuno | I40: Desayuno con Jonathan | J40: 32500 | K40: Efectivo
...

Sheet RESUMEN
A1: Categoría | B1: Detalle | C1: Valor (COP) | D1: INV INICIAL | E1: INV ADICION | F1: INV OPCION | G1: DINERO
A2: INVERSIÓN INICIAL | B2: Mostradores | C2: =SUMIF('INVERSION INICIAL'!B:B,B2,'INVERSION INICIAL'!G:G) -> 700000 | D2: =SUMIF(TD!B:B,B2,TD!C:C) -> 700000 | E2: =SUMIF(TD!F:F,B2,TD!G:G) -> 0 | F2: =SUMIF(TD!J:J,B2,TD!K:K) -> 0
A3: INVERSIÓN INICIAL | B3: Mercancia | C3: =SUMIF('INVERSION INICIAL'!B:B,B3,'INVERSION INICIAL'!G:G) -> 39400000 | D3: =SUMIF(TD!B:B,B3,TD!C:C) -> 39400000 | E3: =SUMIF(TD!F:F,B3,TD!G:G) -> 0 | F3: =SUMIF(TD!J:J,B3,TD!K:K) -> 0 | G3: =D3 -> 39400000
A4: INVERSIÓN INICIAL | B4: Maniquies | C4: =SUMIF('INVERSION INICIAL'!B:B,B4,'INVERSION INICIAL'!G:G) -> 4680315 | D4: =SUMIF(TD!B:B,B4,TD!C:C) -> 4680315 | E4: =SUMIF(TD!F:F,B4,TD!G:G) -> 0 | F4: =SUMIF(TD!J:J,B4,TD!K:K) -> 0 | G4: =D4 -> 4680315
A5: INVERSIÓN INICIAL | B5: Gancheras | C5: =SUMIF('INVERSION INICIAL'!B:B,B5,'INVERSION INICIAL'!G:G) -> 0 | D5: =SUMIF(TD!B:B,B5,TD!C:C) -> 0 | E5: =SUMIF(TD!F:F,B5,TD!G:G) -> 0 | F5: =SUMIF(TD!J:J,B5,TD!K:K) -> 0 | G5: =D5 -> 0
A6: INVERSIÓN INICIAL | B6: Vestier | C6: =SUMIF('INVERSION INICIAL'!B:B,B6,'INVERSION INICIAL'!G:G) -> 380000 | D6: =SUMIF(TD!B:B,B6,TD!C:C) -> 380000 | E6: =SUMIF(TD!F:F,B6,TD!G:G) -> 0 | F6: =SUMIF(TD!J:J,B6,TD!K:K) -> 0
A7: INVERSIÓN INICIAL | B7: Aviso | C7: =SUMIF('INVERSION INICIAL'!B:B,B7,'INVERSION INICIAL'!G:G) -> 400000 | D7: =SUMIF(TD!B:B,B7,TD!C:C) -> 400000 | E7: =SUMIF(TD!F:F,B7,TD!G:G) -> 0 | F7: =SUMIF(TD!J:J,B7,TD!K:K) -> 0
A8: INVERSIÓN INICIAL | B8: Sistema POS | C8: =SUMIF('INVERSION INICIAL'!B:B,B8,'INVERSION INICIAL'!G:G) -> 315600 | D8: =SUMIF(TD!B:B,B8,TD!C:C) -> 315600 | E8: =SUMIF(TD!F:F,B8,TD!G:G) -> 0 | F8: =SUMIF(TD!J:J,B8,TD!K:K) -> 0 | G8: =D8 -> 315600
A9: INVERSIÓN INICIAL | B9: Iluminacion | C9: =SUMIF('INVERSION INICIAL'!B:B,B9,'INVERSION INICIAL'!G:G) -> 600000 | D9: =SUMIF(TD!B:B,B9,TD!C:C) -> 600000 | E9: =SUMIF(TD!F:F,B9,TD!G:G) -> 0 | F9: =SUMIF(TD!J:J,B9,TD!K:K) -> 0 | G9: =D9 -> 600000
A10: INVERSIÓN INICIAL | B10: Computador | C10: =SUMIF('INVERSION INICIAL'!B:B,B10,'INVERSION INICIAL'!G:G) -> 500000 | D10: =SUMIF(TD!B:B,B10,TD!C:C) -> 500000 | E10: =SUMIF(TD!F:F,B10,TD!G:G) -> 0 | F10: =SUMIF(TD!J:J,B10,TD!K:K) -> 0
A11: INVERSIÓN INICIAL | B11: Legalización | C11: =SUMIF('INVERSION INICIAL'!B:B,B11,'INVERSION INICIAL'!G:G) -> 150000 | D11: =SUMIF(TD!B:B,B11,TD!C:C) -> 150000 | E11: =SUMIF(TD!F:F,B11,TD!G:G) -> 0 | F11: =SUMIF(TD!J:J,B11,TD!K:K) -> 0
A12: INVERSIÓN INICIAL | B12: Insumos | C12: =SUMIF('INVERSION INICIAL'!B:B,B12,'INVERSION INICIAL'!G:G) -> 272000 | D12: =SUMIF(TD!B:B,B12,TD!C:C) -> 272000 | E12: =SUMIF(TD!F:F,B12,TD!G:G) -> 0 | F12: =SUMIF(TD!J:J,B12,TD!K:K) -> 0
A13: INVERSIÓN INICIAL | B13: Seguridad | C13: =SUMIF('INVERSION INICIAL'!B:B,B13,'INVERSION INICIAL'!G:G) -> 145800 | D13: =SUMIF(TD!B:B,B13,TD!C:C) -> 145800 | E13: =SUMIF(TD!F:F,B13,TD!G:G) -> 0 | F13: =SUMIF(TD!J:J,B13,TD!K:K) -> 0 | G13: =D13 -> 145800
A14: INVERSIÓN INICIAL | B14: Arreglos locativos | C14: =SUMIF('INVERSION INICIAL'!B:B,B14,'INVERSION INICIAL'!G:G) -> 8044400 | D14: =SUMIF(TD!B:B,B14,TD!C:C) -> 8044400 | E14: =SUMIF(TD!F:F,B14,TD!G:G) -> 0 | F14: =SUMIF(TD!J:J,B14,TD!K:K) -> 0
A15: INVERSIÓN INICIAL | B15: Arriendo | C15: =SUMIF('INVERSION INICIAL'!B:B,B15,'INVERSION INICIAL'!G:G) -> 4000000 | D15: =SUMIF(TD!B:B,B15,TD!C:C) -> 4000000 | E15: =SUMIF(TD!F:F,B15,TD!G:G) -> 0 | F15: =SUMIF(TD!J:J,B15,TD!K:K) -> 0
A16: TOTAL INVERSIÓN | C16: =SUBTOTAL(9,C2:C15) -> 59588115 | D16: =SUBTOTAL(9,D2:D15) -> 59588115 | E16: =SUBTOTAL(9,E2:E15) -> 0 | F16: =SUBTOTAL(9,F2:F15) -> 0
A17: INVERSIÓN INICIAL | B17: Ventas | C17: =SUMIF('INVERSION INICIAL'!B:B,B17,'INVERSION INICIAL'!G:G) -> 0 | D17: =SUMIF(TD!B:B,B17,TD!C:C) -> 0 | E17: =SUMIF(TD!F:F,B17,TD!G:G) -> 0 | F17: =SUMIF(TD!J:J,B17,TD!K:K) -> 0
A19: INVERSION SOCIOS | C19: =C16/C50 -> 14897029
A21: GASTOS FIJOS | B21: Arriendo Local | C21: =SUMIF('GASTOS FIJOS'!B:B,B21,'GASTOS FIJOS'!G:G) -> 3000000
A22: GASTOS FIJOS | B22: Internet | C22: =SUMIF('GASTOS FIJOS'!B:B,B22,'GASTOS FIJOS'!G:G) -> 76000
A23: GASTOS FIJOS | B23: Administración | C23: =SUMIF('GASTOS FIJOS'!B:B,B23,'GASTOS FIJOS'!G:G) -> 5000
A24: GASTOS FIJOS | B24: Sistema POS | C24: =SUMIF('GASTOS FIJOS'!B:B,B24,'GASTOS FIJOS'!G:G) -> 39900
A25: GASTOS FIJOS | B25: Sueldo administrador | C25: =SUMIF('GASTOS FIJOS'!B:B,B25,'GASTOS FIJOS'!G:G) -> 1800000
A26: GASTOS FIJOS | B26: Sueldo auxiliar | C26: =SUMIF('GASTOS FIJOS'!B:B,B26,'GASTOS FIJOS'!G:G) -> 1800000
A27: TOTAL GASTOS FIJOS | C27: =SUBTOTAL(9,C21:C26) -> 6720900
A29: VARIABLES DE OPERACIÓN | B29: Precio Ticket Promedio | C29: 60000
A30: VARIABLES DE OPERACIÓN | B30: Días Abierto al Mes | C30: 30
A31: VARIABLES DE OPERACIÓN | B31: Horario: Lunes a Domingo 9:00 am-8:00 pm
A32: VARIABLES DE OPERACIÓN | B32: Ventas Diarias Estimadas | C32: =OPERACION!C5 -> 12
A34: NOMINA | B34: Empleados | C34: 2
A35: NOMINA | B35: Valor nomina auxiliar | C35: ='GASTOS FIJOS'!G6 -> 1800000
A36: NOMINA | B36: Valor nomina administrador | C36: ='GASTOS FIJOS'!G6 -> 1800000
A39: GASTOS VARIABLES | B39: Luz | C39: =SUMIF(OPERACION!B:B,B39,OPERACION!G:G) -> 270000
A40: GASTOS VARIABLES | B40: Agua | C40: =SUMIF(OPERACION!B:B,B40,OPERACION!G:G) -> 345600
A41: GASTOS VARIABLES | B41: Consumibles | C41: =SUMIF(OPERACION!B:B,B41,OPERACION!G:G) -> 108000
A42: GASTOS VARIABLES | B42: Mercancia | C42: =SUMIF(OPERACION!B:B,B42,OPERACION!G:G) -> 10800000
A43: TOTAL GASTOS VARIABLES | C43: =SUBTOTAL(9,C39:C42) -> 11523600
A45: PROYECCIÓN MENSUAL | B45: Ventas mensuales | C45: =C32*C30 -> 360
A46: INGRESOS | B46: Ingresos Totales | C46: =C45*C29 -> 21600000 | D46: =C46/30 -> 720000
A47: EGRESOS | B47: Gastos fijos mensuales | C47: =C27 -> 6720900
...

Sheet TD

Sheet INVERSION INICIAL
G1: =SUBTOTAL(9,G2:G989) -> 60728115 | I1: =SUBTOTAL(9,I2:I989) -> 0
A2: Categoría | B2: Detalle | C2: Nombre | D2: Especificacion | E2: Cantidad | F2: Valor | G2: Valor Total | H2: Fuente | I2: Link | J2: Clase | K2: Valor 1 | L2: Valor Total 2 | M2: Fuente 2
A3: INVERSIÓN INICIAL | B3: Mercancia | C3: Mercancia inicial | D3: Mercancia inicial | E3: 910 | F3: 40000 | G3: =F3*E3 -> 36400000 | H3: INVERSION INICIAL | J3: PANTALON DAMA | K3: =VLOOKUP(B3,RESUMEN!B:B,1,0) -> Mercancia
A4: INVERSIÓN INICIAL | B4: Mercancia | C4: Mercancia Mauricio | D4: Mercancia Mauricio | E4: 1 | F4: 3000000 | G4: =F4*E4 -> 3000000 | H4: INVERSION INICIAL | J4: INVENTARIOS SIN PAGAR | K4: =VLOOKUP(B4,RESUMEN!B:B,1,0) -> Mercancia
A5: INVERSIÓN INICIAL | B5: Mostradores | C5: Mostrador | D5: Mostrador Principal (Punto de Pago) | E5: 1 | F5: 700000 | G5: =F5*E5 -> 700000 | H5: INVERSION INICIAL | K5: =VLOOKUP(B5,RESUMEN!B:B,1,0) -> Mostradores
A6: INVERSIÓN INICIAL | B6: Maniquies | C6: Maniquies cuerpo Completo | D6: Maniquies Blancos cuerpo Completo | E6: 4 | F6: 280000 | G6: =F6*E6 -> 1120000 | H6: INVERSION INICIAL | K6: =VLOOKUP(B6,RESUMEN!B:B,1,0) -> Maniquies
A7: INVERSIÓN INICIAL | B7: Maniquies | C7: Maniquies medio cuerpo | D7: Maniquies plasticos para Exhibicion | E7: 6 | F7: 59900 | G7: =F7*E7 -> 359400 | H7: INVERSION INICIAL | K7: =VLOOKUP(B7,RESUMEN!B:B,1,0) -> Maniquies
A8: INVERSIÓN INICIAL | B8: Vestier | C8: Cortina Negra | D8: Cortina Negra | E8: 2 | F8: 40000 | G8: =F8*E8 -> 80000 | H8: INVERSION INICIAL | K8: =VLOOKUP(B8,RESUMEN!B:B,1,0) -> Vestier
A9: INVERSIÓN INICIAL | B9: Vestier | C9: Vestier en Drywall | D9: Vestier en Drywall | E9: 2 | F9: 150000 | G9: =F9*E9 -> 300000 | H9: INVERSION INICIAL | K9: =VLOOKUP(B9,RESUMEN!B:B,1,0) -> Vestier
A10: INVERSIÓN INICIAL | B10: Maniquies | C10: Flautas para Exhibicion | D10: Flautas para Exhibicion | E10: 40 | F10: 20000 | G10: =F10*E10 -> 800000 | H10: INVERSION INICIAL | K10: =VLOOKUP(B10,RESUMEN!B:B,1,0) -> Maniquies
A11: INVERSIÓN INICIAL | B11: Maniquies | C11: Cremallera para Flauta | D11: Cremallera para Flauta | E11: 20 | F11: 20000 | G11: =F11*E11 -> 400000 | H11: INVERSION INICIAL | K11: =VLOOKUP(B11,RESUMEN!B:B,1,0) -> Maniquies
A12: INVERSIÓN INICIAL | B12: Maniquies | C12: Ganchera tripode | D12: Ganchera tripode | E12: 2 | F12: 50000 | G12: =F12*E12 -> 100000 | H12: INVERSION INICIAL | K12: =VLOOKUP(B12,RESUMEN!B:B,1,0) -> Maniquies
A13: INVERSIÓN INICIAL | B13: Maniquies | C13: Burro | D13: Burro | E13: 2 | F13: 100000 | G13: =F13*E13 -> 200000 | H13: INVERSION INICIAL | K13: =VLOOKUP(B13,RESUMEN!B:B,1,0) -> Maniquies
A14: INVERSIÓN INICIAL | B14: Maniquies | C14: Mesa para Jeans | D14: Mesa para Jeans | E14: 1 | F14: 100000 | G14: =F14*E14 -> 100000 | H14: INVERSION INICIAL | K14: =VLOOKUP(B14,RESUMEN!B:B,1,0) -> Maniquies
A15: INVERSIÓN INICIAL | B15: Maniquies | C15: Ganchera tripode | D15: Ganchera tripode | E15: 2 | F15: 50000 | G15: =F15*E15 -> 100000 | H15: INVERSION INICIAL | K15: =VLOOKUP(B15,RESUMEN!B:B,1,0) -> Maniquies
A16: INVERSIÓN INICIAL | B16: Maniquies | C16: Ganchos de madera | D16: Ganchos de madera | E16: 645 | F16: 2327 | G16: =F16*E16 -> 1500915 | H16: INVERSION INICIAL | I16: https://www.homecenter.com.co/homecenter-co/product/878775/set-de-15-piezas-ganchos-de-ropa-madera-natural/878775/ | K16: =VLOOKUP(B16,RESUMEN!B:B,1,0) -> Maniquies
A17: INVERSIÓN INICIAL | B17: Aviso | C17: Aviso | D17: Arreglo de aviso nuevo y reutilizacion del que se tiene | E17: 1 | F17: 400000 | G17: =F17*E17 -> 400000 | H17: INVERSION INICIAL | K17: =VLOOKUP(B17,RESUMEN!B:B,1,0) -> Aviso
A18: INVERSIÓN INICIAL | B18: Iluminacion | C18: Iluminacion interna y externa | D18: Iluminacion interna y externa | E18: 1 | F18: 600000 | G18: =F18*E18 -> 600000 | H18: INVERSION INICIAL | K18: =VLOOKUP(B18,RESUMEN!B:B,1,0) -> Iluminacion
A19: INVERSIÓN INICIAL | B19: Computador | C19: Computador | D19: Computador | E19: 1 | F19: 500000 | G19: =F19*E19 -> 500000 | H19: INVERSION INICIAL | K19: =VLOOKUP(B19,RESUMEN!B:B,1,0) -> Computador
A20: INVERSIÓN INICIAL | B20: Sistema POS | C20: Sistema Pos de TiendaNube | D20: Sistema Pos de TiendaNube | E20: 1 | F20: 39900 | G20: =F20*E20 -> 39900 | H20: INVERSION INICIAL | K20: =VLOOKUP(B20,RESUMEN!B:B,1,0) -> Sistema POS
A21: INVERSIÓN INICIAL | B21: Caja registradora | C21: Tiqueteadora | D21: Combo Impresora 58mm + Lector Codigo X-718 + Cajon Monede | E21: 1 | F21: 390000 | G21: =F21*E21 -> 390000 | H21: INVERSION INICIAL | K21: =VLOOKUP(B21,RESUMEN!B:B,1,0) -> #N/A
A22: INVERSIÓN INICIAL | B22: Sistema POS | C22: Equipo Bold | D22: Equipo Bold moderno | E22: 1 | F22: 230000 | G22: =F22*E22 -> 230000 | H22: INVERSION INICIAL | K22: =VLOOKUP(B22,RESUMEN!B:B,1,0) -> Sistema POS
A23: INVERSIÓN INICIAL | B23: Sistema POS | C23: Creacion de dominio | D23: Creacion de dominio | E23: 1 | F23: 45700 | G23: =F23*E23 -> 45700 | H23: INVERSION INICIAL | K23: =VLOOKUP(B23,RESUMEN!B:B,1,0) -> Sistema POS
A24: INVERSIÓN INICIAL | B24: Legalización | C24: Registro Único Tributario (RUT) | D24: Registro Único Tributario (RUT) costo 0 | E24: 1 | F24: 0 | G24: =F24*E24 -> 0 | H24: INVERSION INICIAL | K24: =VLOOKUP(B24,RESUMEN!B:B,1,0) -> Legalización
A25: INVERSIÓN INICIAL | B25: Legalización | C25: Matrícula Mercantil (Cámara de Comercio) | D25: Matrícula Mercantil (Cámara de Comercio de Bogota) | E25: 1 | F25: 150000 | G25: =F25*E25 -> 150000 | H25: INVERSION INICIAL | K25: =VLOOKUP(B25,RESUMEN!B:B,1,0) -> Legalización
A26: INVERSIÓN INICIAL | B26: Legalización | C26: Concepto de Uso de Suelo | D26: Secretaría Distrital de Planeación (Se consulta en línea), Es el documento más crítico antes de firmar el contrato de arrendamiento. Certifica que en esa dirección específica de Suba está permitido operar un "Lavadero de Vehículos". Si el suelo es estrictamente residencial, no te dejarán abrir.Costo: $0 (Gratuito, se descarga por internet con el CHIP del predio) | E26: 1 | F26: 0 | G26: =F26*E26 -> 0 | H26: INVERSION INICIAL | K26: =VLOOKUP(B26,RESUMEN!B:B,1,0) -> Legalización
A27: INVERSIÓN INICIAL | B27: Insumos | C27: Implementos de aseo | D27: Jabon piso, limpiavidrios, ambientador | E27: 1 | F27: 50000 | G27: =F27*E27 -> 50000 | H27: INVERSION INICIAL | K27: =VLOOKUP(B27,RESUMEN!B:B,1,0) -> Insumos
A28: INVERSIÓN INICIAL | B28: Insumos | C28: Señalizacion | D28: Salida de emergencia | E28: 1 | F28: 20000 | G28: =F28*E28 -> 20000 | H28: INVERSION INICIAL | K28: =VLOOKUP(B28,RESUMEN!B:B,1,0) -> Insumos
... A36: INVERSIÓN INICIAL | B36: Arreglos locativos | C36: Pin antihurto | D36: Alarma Pin Etiqueta Am Antihurto Tienda Ropa X 1000 Unds | E36: 1 | F36: 1187500 | G36: =F36*E36 -> 1187500 | H36: INVERSION INICIAL | K36: =VLOOKUP(B36,RESUMEN!B:B,1,0) -> Arreglos locativos
A37: INVERSIÓN INICIAL | B37: Seguridad | C37: Candados | D37: Candados | E37: 2 | F37: 42900 | G37: =F37*E37 -> 85800 | H37: INVERSION INICIAL | I37: https://www.homecenter.com.co/homecenter-co/category/cat10662/candados/?kid=dis_adi_1435635&gad_source=1&gad_campaignid=23795319996&gbraid=0AAAAADt6wnoJ5ATpOuCvWSc2VjYD7ZXkR&gclid=CjwKCAjw8uTQBhAdEiwAVvtJyoKJyojXEy2y_DjK7sS4mNBKn8yVvvttGfSm34YsEuaMp2Dz6lf3hBoCyjQQAvD_BwE | K37: =VLOOKUP(B37,RESUMEN!B:B,1,0) -> Seguridad
A38: INVERSIÓN INICIAL | B38: Seguridad | C38: Cambio de guardas | D38: Cambio de guardas | E38: 1 | F38: 60000 | G38: =F38*E38 -> 60000 | H38: INVERSION INICIAL | K38: =VLOOKUP(B38,RESUMEN!B:B,1,0) -> Seguridad
A39: INVERSIÓN INICIAL | B39: Arreglos locativos | C39: Pintura | D39: Pintura Blanca | E39: 1 | F39: 284900 | G39: =F39*E39 -> 284900 | H39: INVERSION INICIAL | K39: =VLOOKUP(B39,RESUMEN!B:B,1,0) -> Arreglos locativos
A40: INVERSIÓN INICIAL | B40: Arreglos locativos | C40: Pintura | D40: Pintura Amarilla | E40: 1 | F40: 72000 | G40: =F40*E40 -> 72000 | H40: INVERSION INICIAL | K40: =VLOOKUP(B40,RESUMEN!B:B,1,0) -> Arreglos locativos
A41: INVERSIÓN INICIAL | B41: Arreglos locativos | C41: Piso | D41: Piso Laminado | E41: 0 | F41: 4000000 | G41: =F41*E41 -> 0 | H41: INVERSION OPCIONAL | K41: =VLOOKUP(B41,RESUMEN!B:B,1,0) -> Arreglos locativos
A42: INVERSIÓN INICIAL | B42: Arreglos locativos | C42: Decoracion | D42: Decoracion | E42: 1 | F42: 600000 | G42: =F42*E42 -> 600000 | H42: INVERSION INICIAL | K42: =VLOOKUP(B42,RESUMEN!B:B,1,0) -> Arreglos locativos
A43: INVERSIÓN INICIAL | B43: Arreglos locativos | C43: Vidrios vitrinas entrada | D43: 2 Vidrios vitrinas entrada de 83 cm en vidrio de seguridad de 8 mm | E43: 2 | F43: 450000 | G43: =F43*E43 -> 900000 | H43: INVERSION INICIAL | K43: =VLOOKUP(B43,RESUMEN!B:B,1,0) -> Arreglos locativos
A44: INVERSIÓN INICIAL | B44: Arriendo | C44: Arriendo inicial | D44: Arriendo inicial | E44: 1 | F44: 4000000 | G44: =F44*E44 -> 4000000 | H44: INVERSION INICIAL | K44: =VLOOKUP(B44,RESUMEN!B:B,1,0) -> Arriendo

Sheet GASTOS FIJOS
G1: =SUBTOTAL(9,G2:G1006) -> 6720900
A2: Categoría | B2: Detalle | C2: Nombre | D2: Especificacion | E2: Cantidad | F2: Valor | G2: Valor Total | H2: Fuente | I2: Telefono | J2: Tarea/observacion | K2: Valor 2 | L2: Valor Total 2 | M2: Fuente 2
A3: GASTOS FIJOS | B3: Arriendo Local | C3: Arriendo Local 25 metros cuadrados | D3: Arriendo Local 25 metros cuadrados | E3: 1 | F3: 3000000 | G3: =F3*E3 -> 3000000 | L3: =K3*E3 -> 0
A4: GASTOS FIJOS | B4: Internet | C4: Internet de 900 megas | D4: Internet de 900 megas movistar | E4: 1 | F4: 76000 | G4: =F4*E4 -> 76000 | H4: https://solucionesmovilyhogar.com/hogar?gad_source=1&gad_campaignid=22638574230&gbraid=0AAAAA-JBuZhpF13EfpX-c8woTOOPZEJRZ&gclid=CjwKCAjwtIfPBhAzEiwAv9RTJoUE7cL_c3ZNPoNtGFPMOVhliD3aVdMV2p4zjMf7SFBtoiGfyQi0dxoCfigQAvD_BwE | L4: =K4*E4 -> 0
A5: GASTOS FIJOS | B5: Administración | C5: Esferos, tablas, impresiones, libro | D5: Esferos, tablas, impresiones, libro | E5: 1 | F5: 5000 | G5: =F5*E5 -> 5000 | L5: =K5*E5 -> 0
A6: GASTOS FIJOS | B6: Sueldo auxiliar | C6: Sueldo 7 horas auxiliar tarde | D6: Sueldo auxiliar | E6: 30 | F6: 60000 | G6: =F6*E6 -> 1800000 | L6: =K6*E6 -> 0
A7: GASTOS FIJOS | B7: Sueldo administrador | C7: Sueldo 3 horas administrador mañana | D7: Mauricio Garzon | E7: 30 | F7: 60000 | G7: =F7*E7 -> 1800000 | L7: =K7*E7 -> 0
A8: GASTOS FIJOS | B8: Sistema POS | C8: Sistema Pos de TiendaNube | D8: Sistema Pos de TiendaNube | E8: 1 | F8: 39900 | G8: =F8*E8 -> 39900 | L8: =K8*E8 -> 0
G9: =F9*E9 -> 0 | L9: =K9*E9 -> 0
G10: =F10*E10 -> 0 | L10: =K10*E10 -> 0
G11: =F11*E11 -> 0 | L11: =K11*E11 -> 0
G12: =F12*E12 -> 0 | L12: =K12*E12 -> 0
G13: =F13*E13 -> 0 | L13: =K13*E13 -> 0
G14: =F14*E14 -> 0 | L14: =K14*E14 -> 0
G15: =F15*E15 -> 0 | L15: =K15*E15 -> 0
G16: =F16*E16 -> 0 | L16: =K16*E16 -> 0
G17: =F17*E17 -> 0 | L17: =K17*E17 -> 0
G18: =F18*E18 -> 0 | L18: =K18*E18 -> 0
G19: =F19*E19 -> 0 | L19: =K19*E19 -> 0
G20: =F20*E20 -> 0 | L20: =K20*E20 -> 0
... G50: =F50*E50 -> 0 | L50: =K50*E50 -> 0

Sheet OPERACION
A1: Categoría | B1: Detalle | C1: Valor (COP)
A2: VARIABLES DE OPERACIÓN | B2: Precio Ticket Promedio | C2: =RESUMEN!C29 -> 60000
A3: VARIABLES DE OPERACIÓN | B3: Días Abierto al Mes | C3: 30
A4: VARIABLES DE OPERACIÓN | B4: Horario: Lunes a Viernes 10:00 am-9:00 pm Sabado-Domingo 9 am-8:30 pm
A5: VARIABLES DE OPERACIÓN | B5: Ventas diarias estimadas | C5: 12
A6: VARIABLES DE OPERACIÓN | B6: Ventas mensuales estimadas | C6: =C5*C3 -> 360
A7: VARIABLES DE OPERACIÓN | B7: Empleados | C7: 2
H8: =1-H9/C2 -> 0.4665
G9: =SUBTOTAL(9,G10:G1002) -> 11523600 | H9: =SUBTOTAL(9,H10:H1002) -> 32010
A10: Categoría | B10: Detalle | C10: Nombre | D10: Volumen | E10: Cantidad | F10: Valor | G10: Valor Total | H10: Valor Unt
A11: GASTOS VARIABLES | B11: Luz | C11: Luz | D11: Gasto: 0.5 kWh de energía por moto. | E11: 0.5 | F11: 1500 | G11: =F11*E11*$C$6 -> 270000 | H11: =E11*F11 -> 750
A12: GASTOS VARIABLES | B12: Agua | C12: Agua | D12: Gasto: 60 Litros por moto. 0,06 m3 | E12: 0.06 | F12: 16000 | G12: =F12*E12*$C$6 -> 345600 | H12: =E12*F12 -> 960
A13: GASTOS VARIABLES | B13: Consumibles | C13: Escobas y traperos | E13: 1 | F13: 100 | G13: =F13*E13*$C$6 -> 36000 | H13: =E13*F13 -> 100
A14: GASTOS VARIABLES | B14: Consumibles | C14: Implementos de aseo | D14: Jabon piso, limpiavidrios, ambientador | E14: 1 | F14: 200 | G14: =F14*E14*$C$6 -> 72000 | H14: =E14*F14 -> 200
A15: GASTOS VARIABLES | B15: Mercancia | C15: Mercancia | E15: 1 | F15: 30000 | G15: =F15*E15*$C$6 -> 10800000 | H15: =E15*F15 -> 30000

Sheet CRONOGRAMA
A1: Arriendo | B1: ok
A2: RUT | B2: ok
A3: nombre | B3: tienda.Be casual | C3: Vístete para ser tú mismo. | D3: Comodidad que se nota. Estilo que se siente.
A4: dirección | B4: Calle 132 # 92-32
A5: celular | B5: 3115929346
A6: correo | B6: ventas@tiendabecasual.com
A7: CCB | B7: ok
A8: monto | B8: 2 millones
A9: CCTV | B9: ok
A10: Facturación
A11: sistema POS
A12: Computador | B12: ok
A14: Medios de pago
A15: Nequi | B15: Mauricio
A16: Daviplata | B16: Diana
A17: Addi | B17: Yeni
A18: Sistecredito | B18: Yeni
A19: cuenta ahorros | B19: Yeni
A20: Bold | B20: Yeni
A22: aviso
A23: nombre
A24: tipo de letra del nombre | B24: Montserrat Black o Futura Bold | C24: monserrat
A25: colores del nombre | B25: Negro, Gris y Amarillo
A26: vidrios
A27: pintura
A28: madera
A29: luces | B29: ok
A30: maniquíes | B30: ok
A31: ganchos | B31: ok
A32: Vestier cortinas | B32: ok | C32: tubos y soporte de tubos
A35: escoba
A36: recogedor
A37: trapero
A38: toallas
A39: desinfectante
A40: jabón rey
A41: Señalizacion
A42: Canecas | B42: ok
A43: Papeleria
A44: Extintor | B44: ok
...

Sheet COMPRAS
F1: =SUBTOTAL(9,F3:F1014) -> 1821 | H1: =SUBTOTAL(9,H3:H1014) -> 30043296 | I1: 2 | K1: =SUBTOTAL(9,K3:K1014) -> 60266000
A3: FECHA INGRESO | B3: SKU | C3: CODIGO DE BARRAS | D3: NOMBRE COMPLETO | E3: PROVEEDOR-MARCA | F3: CANTIDAD COMPRA | G3: VALOR UNT | H3: VALOR TOTAL COMPRA | I3: PRECIO DE VENTA | J3: % MARGEN | K3: VALOR TOTAL VENTA
A4: 46186 | B4: 1143 | C4: =VLOOKUP(B4,MAESTRA!I:K,2,0) -> *1143* | D4: =VLOOKUP(B4,MAESTRA!I:K,3,0) -> JEANS DAMA 4 BOTONES TALLA 10 | E4: R TREIK | F4: 2 | G4: 32000 | H4: =G4*F4 -> 64000 | I4: =CEILING(G4*$I$1,1000) -> 64000 | J4: =IFERROR((I4-G4)/G4,"") -> 1 | K4: =I4*F4 -> 128000
A5: 46186 | B5: 1142 | C5: =VLOOKUP(B5,MAESTRA!I:K,2,0) -> *1142* | D5: =VLOOKUP(B5,MAESTRA!I:K,3,0) -> JEANS DAMA 4 BOTONES TALLA 8 | E5: R TREIK | F5: 1 | G5: 32000 | H5: =G5*F5 -> 32000 | I5: =CEILING(G5*$I$1,1000) -> 64000 | J5: =IFERROR((I5-G5)/G5,"") -> 1 | K5: =I5*F5 -> 64000
A6: 46186 | B6: 1152 | C6: =VLOOKUP(B6,MAESTRA!I:K,2,0) -> *1152* | D6: =VLOOKUP(B6,MAESTRA!I:K,3,0) -> JEANS DAMA 4 BOTONES SIN BOLSILLO TALLA 8 | E6: R TREIK | F6: 1 | G6: 32000 | H6: =G6*F6 -> 32000 | I6: =CEILING(G6*$I$1,1000) -> 64000 | J6: =IFERROR((I6-G6)/G6,"") -> 1 | K6: =I6*F6 -> 64000
A7: 46186 | B7: 1146 | C7: =VLOOKUP(B7,MAESTRA!I:K,2,0) -> *1146* | D7: =VLOOKUP(B7,MAESTRA!I:K,3,0) -> JEANS DAMA 4 BOTONES TALLA 16 | E7: R TREIK | F7: 2 | G7: 32000 | H7: =G7*F7 -> 64000 | I7: =CEILING(G7*$I$1,1000) -> 64000 | J7: =IFERROR((I7-G7)/G7,"") -> 1 | K7: =I7*F7 -> 128000
A8: 46186 | B8: 1156 | C8: =VLOOKUP(B8,MAESTRA!I:K,2,0) -> *1156* | D8: =VLOOKUP(B8,MAESTRA!I:K,3,0) -> JEANS DAMA 4 BOTONES SIN BOLSILLO TALLA 16 | E8: R TREIK | F8: 1 | G8: 32000 | H8: =G8*F8 -> 32000 | I8: =CEILING(G8*$I$1,1000) -> 64000 | J8: =IFERROR((I8-G8)/G8,"") -> 1 | K8: =I8*F8 -> 64000
A9: 46186 | B9: 1114 | C9: =VLOOKUP(B9,MAESTRA!I:K,2,0) -> *1114* | D9: =VLOOKUP(B9,MAESTRA!I:K,3,0) -> JEANS DAMA 1 BOTON TALLA 12 | E9: R TREIK | F9: 1 | G9: 32000 | H9: =G9*F9 -> 32000 | I9: =CEILING(G9*$I$1,1000) -> 64000 | J9: =IFERROR((I9-G9)/G9,"") -> 1 | K9: =I9*F9 -> 64000
A10: 46186 | B10: 1145 | C10: =VLOOKUP(B10,MAESTRA!I:K,2,0) -> *1145* | D10: =VLOOKUP(B10,MAESTRA!I:K,3,0) -> JEANS DAMA 4 BOTONES TALLA 14 | E10: R TREIK | F10: 1 | G10: 32000 | H10: =G10*F10 -> 32000 | I10: =CEILING(G10*$I$1,1000) -> 64000 | J10: =IFERROR((I10-G10)/G10,"") -> 1 | K10: =I10*F10 -> 64000
A11: 46186 | B11: 1125 | C11: =VLOOKUP(B11,MAESTRA!I:K,2,0) -> *1125* | D11: =VLOOKUP(B11,MAESTRA!I:K,3,0) -> JEANS DAMA 1 BOTON BOTA RECTA TALLA 14 | E11: R TREIK | F11: 2 | G11: 38000 | H11: =G11*F11 -> 76000 | I11: =CEILING(G11*$I$1,1000) -> 76000 | J11: =IFERROR((I11-G11)/G11,"") -> 1 | K11: =I11*F11 -> 152000
A12: 46186 | B12: 1123 | C12: =VLOOKUP(B12,MAESTRA!I:K,2,0) -> *1123* | D12: =VLOOKUP(B12,MAESTRA!I:K,3,0) -> JEANS DAMA 1 BOTON BOTA RECTA TALLA 10 | E12: R TREIK | F12: 1 | G12: 38000 | H12: =G12*F12 -> 38000 | I12: =CEILING(G12*$I$1,1000) -> 76000 | J12: =IFERROR((I12-G12)/G12,"") -> 1 | K12: =I12*F12 -> 76000
A13: 46186 | B13: 1122 | C13: =VLOOKUP(B13,MAESTRA!I:K,2,0) -> *1122* | D13: =VLOOKUP(B13,MAESTRA!I:K,3,0) -> JEANS DAMA 1 BOTON BOTA RECTA TALLA 8 | E13: R TREIK | F13: 1 | G13: 38000 | H13: =G13*F13 -> 38000 | I13: =CEILING(G13*$I$1,1000) -> 76000 | J13: =IFERROR((I13-G13)/G13,"") -> 1 | K13: =I13*F13 -> 76000
A14: 46186 | B14: 1125 | C14: =VLOOKUP(B14,MAESTRA!I:K,2,0) -> *1125* | D14: =VLOOKUP(B14,MAESTRA!I:K,3,0) -> JEANS DAMA 1 BOTON BOTA RECTA TALLA 14 | E14: R TREIK | F14: 2 | G14: 32000 | H14: =G14*F14 -> 64000 | I14: =CEILING(G14*$I$1,1000) -> 64000 | J14: =IFERROR((I14-G14)/G14,"") -> 1 | K14: =I14*F14 -> 128000
A15: 46186 | B15: 1155 | C15: =VLOOKUP(B15,MAESTRA!I:K,2,0) -> *1155* | D15: =VLOOKUP(B15,MAESTRA!I:K,3,0) -> JEANS DAMA 4 BOTONES SIN BOLSILLO TALLA 14 | E15: R TREIK | F15: 1 | G15: 32000 | H15: =G15*F15 -> 32000 | I15: =CEILING(G15*$I$1,1000) -> 64000 | J15: =IFERROR((I15-G15)/G15,"") -> 1 | K15: =I15*F15 -> 64000
... A38: 46186 | B38: 5112131 | C38: =VLOOKUP(B38,MAESTRA!I:K,2,0) -> *5112131* | D38: =VLOOKUP(B38,MAESTRA!I:K,3,0) -> BERMUDAS DAMA DRILL TALLA VA | E38: GOLDTEX | F38: 9 | G38: 26000 | H38: =G38*F38 -> 234000 | I38: =CEILING(G38*$I$1,1000) -> 52000 | J38: =IFERROR((I38-G38)/G38,"") -> 1 | K38: =I38*F38 -> 468000
A39: 46186 | B39: 1212110 | C39: =VLOOKUP(B39,MAESTRA!I:K,2,0) -> *1212110* | D39: =VLOOKUP(B39,MAESTRA!I:K,3,0) -> PERFUMES DAMA PINK MINI | F39: 9 | G39: 5000 | H39: =G39*F39 -> 45000 | I39: =CEILING(G39*$I$1,1000) -> 10000 | J39: =IFERROR((I39-G39)/G39,"") -> 1 | K39: =I39*F39 -> 90000
A40: 46186 | B40: 4711600 | C40: =VLOOKUP(B40,MAESTRA!I:K,2,0) -> *4711600* | D40: =VLOOKUP(B40,MAESTRA!I:K,3,0) -> BRILLO DAMA LABIAL | F40: 6 | G40: 2500 | H40: =G40*F40 -> 15000 | I40: =CEILING(G40*$I$1,1000) -> 5000 | J40: =IFERROR((I40-G40)/G40,"") -> 1 | K40: =I40*F40 -> 30000
A41: 46186 | B41: 46100 | C41: =VLOOKUP(B41,MAESTRA!I:K,2,0) -> *46100* | D41: =VLOOKUP(B41,MAESTRA!I:K,3,0) -> SPLASH DAMA - | F41: 2 | G41: 8500 | H41: =G41*F41 -> 17000 | I41: =CEILING(G41*$I$1,1000) -> 17000 | J41: =IFERROR((I41-G41)/G41,"") -> 1 | K41: =I41*F41 -> 34000
A42: 46186 | B42: 46200 | C42: =VLOOKUP(B42,MAESTRA!I:K,2,0) -> *46200* | D42: =VLOOKUP(B42,MAESTRA!I:K,3,0) -> SPLASH CABALLERO - | F42: 2 | G42: 6500 | H42: =G42*F42 -> 13000 | I42: =CEILING(G42*$I$1,1000) -> 13000 | J42: =IFERROR((I42-G42)/G42,"") -> 1 | K42: =I42*F42 -> 26000
A43: 46186 | B43: 1438630 | C43: =VLOOKUP(B43,MAESTRA!I:K,2,0) -> *1438630* | D43: =VLOOKUP(B43,MAESTRA!I:K,3,0) -> GORRAS UNISEX COLOMBIA TALLA UN | E43: GORRAS LOS ANGELES | F43: 6 | G43: 28000 | H43: =G43*F43 -> 168000 | I43: =CEILING(G43*$I$1,1000) -> 56000 | J43: =IFERROR((I43-G43)/G43,"") -> 1 | K43: =I43*F43 -> 336000
A44: 46186 | B44: 14327530 | C44: =VLOOKUP(B44,MAESTRA!I:K,2,0) -> *14327530* | D44: =VLOOKUP(B44,MAESTRA!I:K,3,0) -> GORRAS UNISEX VARIOS TALLA UN | E44: GORRAS LOS ANGELES | F44: 17 | G44: 16000 | H44: =G44*F44 -> 272000 | I44: =CEILING(G44*$I$1,1000) -> 32000 | J44: =IFERROR((I44-G44)/G44,"") -> 1 | K44: =I44*F44 -> 544000
A45: 46186 | B45: 1532540 | C45: =VLOOKUP(B45,MAESTRA!I:K,2,0) -> *1532540* | D45: =VLOOKUP(B45,MAESTRA!I:K,3,0) -> MALETAS UNISEX SPRAY GROUND | E45: BALU BAGS | F45: 1 | G45: 60000 | H45: =G45*F45 -> 60000 | I45: =CEILING(G45*$I$1,1000) -> 120000 | J45: =IFERROR((I45-G45)/G45,"") -> 1 | K45: =I45*F45 -> 120000
A46: 46186 | B46: 161480 | C46: =VLOOKUP(B46,MAESTRA!I:K,2,0) -> *161480* | D46: =VLOOKUP(B46,MAESTRA!I:K,3,0) -> LLAVEROS DAMA BOMBA | E46: BALU BAGS | F46: 6 | G46: 6000 | H46: =G46*F46 -> 36000 | I46: =CEILING(G46*$I$1,1000) -> 12000 | J46: =IFERROR((I46-G46)/G46,"") -> 1 | K46: =I46*F46 -> 72000
A47: 46186 | B47: 161720 | C47: =VLOOKUP(B47,MAESTRA!I:K,2,0) -> *161720* | D47: =VLOOKUP(B47,MAESTRA!I:K,3,0) -> LLAVEROS DAMA CEREZAS BRILLANTE | E47: BALU BAGS | F47: 2 | G47: 17000 | H47: =G47*F47 -> 34000 | I47: =CEILING(G47*$I$1,1000) -> 34000 | J47: =IFERROR((I47-G47)/G47,"") -> 1 | K47: =I47*F47 -> 68000
A48: 46186 | B48: 171460 | C48: =VLOOKUP(B48,MAESTRA!I:K,2,0) -> *171460* | D48: =VLOOKUP(B48,MAESTRA!I:K,3,0) -> BOLSOS DAMA BAUL | E48: BALU BAGS | F48: 1 | G48: 45000 | H48: =G48*F48 -> 45000 | I48: =CEILING(G48*$I$1,1000) -> 90000 | J48: =IFERROR((I48-G48)/G48,"") -> 1 | K48: =I48*F48 -> 90000
A49: 46186 | B49: 221030 | C49: =VLOOKUP(B49,MAESTRA!I:K,2,0) -> *221030* | D49: =VLOOKUP(B49,MAESTRA!I:K,3,0) -> CORREAS DAMA - TALLA UN | E49: BALU BAGS | F49: 6 | G49: 9000 | H49: =G49*F49 -> 54000 | I49: =CEILING(G49*$I$1,1000) -> 18000 | J49: =IFERROR((I49-G49)/G49,"") -> 1 | K49: =I49*F49 -> 108000
A50: 46186 | B50: 171570 | C50: =VLOOKUP(B50,MAESTRA!I:K,2,0) -> *171570* | D50: =VLOOKUP(B50,MAESTRA!I:K,3,0) -> BOLSOS DAMA CADENA DORADA | E50: BALU BAGS | F50: 1 | G50: 30000 | H50: =G50*F50 -> 30000 | I50: =CEILING(G50*$I$1,1000) -> 60000 | J50: =IFERROR((I50-G50)/G50,"") -> 1 | K50: =I50*F50 -> 60000
A51: 46186 | B51: 183130 | C51: =VLOOKUP(B51,MAESTRA!I:K,2,0) -> *183130* | D51: =VLOOKUP(B51,MAESTRA!I:K,3,0) -> CARRIEL UNISEX ADIDAS | E51: BALU BAGS | F51: 2 | G51: 24000 | H51: =G51*F51 -> 48000 | I51: =CEILING(G51*$I$1,1000) -> 48000 | J51: =IFERROR((I51-G51)/G51,"") -> 1 | K51: =I51*F51 -> 96000
A52: 46186 | B52: 1921180 | C52: =VLOOKUP(B52,MAESTRA!I:K,2,0) -> *1921180* | D52: =VLOOKUP(B52,MAESTRA!I:K,3,0) -> PECHERAS CABALLERO DIFERENTES MARCAS | E52: BALU BAGS | F52: 3 | G52: 24000 | H52: =G52*F52 -> 72000 | I52: =CEILING(G52*$I$1,1000) -> 48000 | J52: =IFERROR((I52-G52)/G52,"") -> 1 | K52: =I52*F52 -> 144000
A53: 46186 | B53: 201540 | C53: =VLOOKUP(B53,MAESTRA!I:K,2,0) -> *201540* | D53: =VLOOKUP(B53,MAESTRA!I:K,3,0) -> CANGUROS DAMA BRILLO | E53: BALU BAGS | F53: 1 | G53: 38000 | H53: =G53*F53 -> 38000 | I53: =CEILING(G53*$I$1,1000) -> 76000 | J53: =IFERROR((I53-G53)/G53,"") -> 1 | K53: =I53*F53 -> 76000
A54: 46186 | B54: 203130 | C54: =VLOOKUP(B54,MAESTRA!I:K,2,0) -> *203130* | D54: =VLOOKUP(B54,MAESTRA!I:K,3,0) -> CANGUROS UNISEX ADIDAS | E54: BALU BAGS | F54: 2 | G54: 20000 | H54: =G54*F54 -> 40000 | I54: =CEILING(G54*$I$1,1000) -> 40000 | J54: =IFERROR((I54-G54)/G54,"") -> 1 | K54: =I54*F54 -> 80000
... A262: 46186 | B262: 1153 | C262: =VLOOKUP(B262,MAESTRA!I:K,2,0) -> *1153* | D262: =VLOOKUP(B262,MAESTRA!I:K,3,0) -> JEANS DAMA 4 BOTONES SIN BOLSILLO TALLA 10 | E262: R TREIK | F262: 1 | G262: 32000 | H262: =G262*F262 -> 32000 | I262: =CEILING(G262*$I$1,1000) -> 64000 | J262: =IFERROR((I262-G262)/G262,"") -> 1 | K262: =I262*F262 -> 64000
A263: 46186 | B263: 35211328 | C263: =VLOOKUP(B263,MAESTRA!I:K,2,0) -> *35211328* | D263: =VLOOKUP(B263,MAESTRA!I:K,3,0) -> PANTALONETAS CABALLERO DEPORTIVA TALLA S-M | F263: 1 | G263: 22000 | H263: =G263*F263 -> 22000 | I263: =CEILING(G263*$I$1,1000) -> 44000 | J263: =IFERROR((I263-G263)/G263,"") -> 1 | K263: =I263*F263 -> 44000
A264: 46186 | B264: 2832531 | C264: =VLOOKUP(B264,MAESTRA!I:K,2,0) -> *2832531* | D264: =VLOOKUP(B264,MAESTRA!I:K,3,0) -> ANILLOS UNISEX ANILLO 1 TALLA VA | E264: DIVAS | F264: 5 | G264: 10500 | H264: =G264*F264 -> 52500 | I264: =CEILING(G264*$I$1,1000) -> 21000 | J264: =IFERROR((I264-G264)/G264,"") -> 1 | K264: =I264*F264 -> 105000
A265: 46186 | B265: 2832631 | C265: =VLOOKUP(B265,MAESTRA!I:K,2,0) -> *2832631* | D265: =VLOOKUP(B265,MAESTRA!I:K,3,0) -> ANILLOS UNISEX ANILLO 2 TALLA VA | E265: DIVAS | F265: 4 | G265: 6500 | H265: =G265*F265 -> 26000 | I265: =CEILING(G265*$I$1,1000) -> 13000 | J265: =IFERROR((I265-G265)/G265,"") -> 1 | K265: =I265*F265 -> 52000
A266: 46186 | B266: 2832731 | C266: =VLOOKUP(B266,MAESTRA!I:K,2,0) -> *2832731* | D266: =VLOOKUP(B266,MAESTRA!I:K,3,0) -> ANILLOS UNISEX ANILLO 3 TALLA VA | E266: DIVAS | F266: 1 | G266: 4500 | H266: =G266*F266 -> 4500 | I266: =CEILING(G266*$I$1,1000) -> 9000 | J266: =IFERROR((I266-G266)/G266,"") -> 1 | K266: =I266*F266 -> 9000
A267: 46186 | B267: 2832831 | C267: =VLOOKUP(B267,MAESTRA!I:K,2,0) -> *2832831* | D267: =VLOOKUP(B267,MAESTRA!I:K,3,0) -> ANILLOS UNISEX ANILLO 4 TALLA VA | E267: DIVAS | F267: 2 | G267: 8000 | H267: =G267*F267 -> 16000 | I267: =CEILING(G267*$I$1,1000) -> 16000 | J267: =IFERROR((I267-G267)/G267,"") -> 1 | K267: =I267*F267 -> 32000
A268: 46186 | B268: 2832931 | C268: =VLOOKUP(B268,MAESTRA!I:K,2,0) -> *2832931* | D268: =VLOOKUP(B268,MAESTRA!I:K,3,0) -> ANILLOS UNISEX ANILLO 5 TALLA VA | E268: DIVAS | F268: 1 | G268: 11000 | H268: =G268*F268 -> 11000 | I268: =CEILING(G268*$I$1,1000) -> 22000 | J268: =IFERROR((I268-G268)/G268,"") -> 1 | K268: =I268*F268 -> 22000
A269: 46186 | B269: 2833031 | C269: =VLOOKUP(B269,MAESTRA!I:K,2,0) -> *2833031* | D269: =VLOOKUP(B269,MAESTRA!I:K,3,0) -> ANILLOS UNISEX ANILLO 6 TALLA VA | E269: DIVAS | F269: 1 | G269: 6000 | H269: =G269*F269 -> 6000 | I269: =CEILING(G269*$I$1,1000) -> 12000 | J269: =IFERROR((I269-G269)/G269,"") -> 1 | K269: =I269*F269 -> 12000
A270: 46186 | B270: 2833131 | C270: =VLOOKUP(B270,MAESTRA!I:K,2,0) -> *2833131* | D270: =VLOOKUP(B270,MAESTRA!I:K,3,0) -> ANILLOS UNISEX ANILLO 7 TALLA VA | E270: DIVAS | F270: 1 | G270: 9000 | H270: =G270*F270 -> 9000 | I270: =CEILING(G270*$I$1,1000) -> 18000 | J270: =IFERROR((I270-G270)/G270,"") -> 1 | K270: =I270*F270 -> 18000
...

Sheet IMPRESION
A1: CODIGO | B1: 1143
A2: DESCRIPCION | B2: =VLOOKUP(B1,COMPRAS!B:I,3,0) -> JEANS DAMA 4 BOTONES TALLA 10
A3: VALOR | B3: =VLOOKUP(B1,COMPRAS!B:I,7,0) -> 64000
A4: CODIGOBARRA | B4: =VLOOKUP(B1,COMPRAS!B:I,2,0) -> *1143*
A5: CANTIDAD ETIQUETAS | B5: 2

Sheet MAESTRA
A3: FECHA CREACION | B3: LINEA | C3: CATEGORIA | D3: GENERO | E3: ESTILO-DETALLE | F3: COLOR | G3: TALLA | H3: PROVEEDOR-MARCA | I3: SKU | J3: CODIGO DE BARRAS | K3: NOMBRE COMPLETO
A4: 46186 | B4: ROPA DAMA | C4: JEANS | D4: DAMA | E4: 4 BOTONES | F4: GRIS | G4: 10 | H4: R TREIK | I4: =IFERROR(CONCATENATE(VLOOKUP(C4,PARAM!D:E,2,0),VLOOKUP(D4,PARAM!J:K,2,0),VLOOKUP(E4,PARAM!G:H,2,0),VLOOKUP(G4,PARAM!P:Q,2,0)),"") -> 1143 | J4: =IFERROR(CONCATENATE("*",VLOOKUP(C4,PARAM!D:E,2,0),VLOOKUP(D4,PARAM!J:K,2,0),VLOOKUP(E4,PARAM!G:H,2,0),VLOOKUP(G4,PARAM!P:Q,2,0),"*"),"") -> *1143* | K4: =CONCATENATE(C4," ",D4," ",E4,IF(G4="-","",CONCATENATE(" TALLA ",G4))) -> JEANS DAMA 4 BOTONES TALLA 10
A5: 46186 | B5: ROPA DAMA | C5: JEANS | D5: DAMA | E5: 4 BOTONES | F5: GRIS | G5: 8 | H5: R TREIK | I5: =IFERROR(CONCATENATE(VLOOKUP(C5,PARAM!D:E,2,0),VLOOKUP(D5,PARAM!J:K,2,0),VLOOKUP(E5,PARAM!G:H,2,0),VLOOKUP(G5,PARAM!P:Q,2,0)),"") -> 1142 | J5: =IFERROR(CONCATENATE("*",VLOOKUP(C5,PARAM!D:E,2,0),VLOOKUP(D5,PARAM!J:K,2,0),VLOOKUP(E5,PARAM!G:H,2,0),VLOOKUP(G5,PARAM!P:Q,2,0),"*"),"") -> *1142* | K5: =CONCATENATE(C5," ",D5," ",E5,IF(G5="-","",CONCATENATE(" TALLA ",G5))) -> JEANS DAMA 4 BOTONES TALLA 8
A6: 46186 | B6: ROPA DAMA | C6: JEANS | D6: DAMA | E6: 4 BOTONES SIN BOLSILLO | F6: GRIS | G6: 8 | H6: R TREIK | I6: =IFERROR(CONCATENATE(VLOOKUP(C6,PARAM!D:E,2,0),VLOOKUP(D6,PARAM!J:K,2,0),VLOOKUP(E6,PARAM!G:H,2,0),VLOOKUP(G6,PARAM!P:Q,2,0)),"") -> 1152 | J6: =IFERROR(CONCATENATE("*",VLOOKUP(C6,PARAM!D:E,2,0),VLOOKUP(D6,PARAM!J:K,2,0),VLOOKUP(E6,PARAM!G:H,2,0),VLOOKUP(G6,PARAM!P:Q,2,0),"*"),"") -> *1152* | K6: =CONCATENATE(C6," ",D6," ",E6,IF(G6="-","",CONCATENATE(" TALLA ",G6))) -> JEANS DAMA 4 BOTONES SIN BOLSILLO TALLA 8
A7: 46186 | B7: ROPA DAMA | C7: JEANS | D7: DAMA | E7: 4 BOTONES | F7: GRIS | G7: 16 | H7: R TREIK | I7: =IFERROR(CONCATENATE(VLOOKUP(C7,PARAM!D:E,2,0),VLOOKUP(D7,PARAM!J:K,2,0),VLOOKUP(E7,PARAM!G:H,2,0),VLOOKUP(G7,PARAM!P:Q,2,0)),"") -> 1146 | J7: =IFERROR(CONCATENATE("*",VLOOKUP(C7,PARAM!D:E,2,0),VLOOKUP(D7,PARAM!J:K,2,0),VLOOKUP(E7,PARAM!G:H,2,0),VLOOKUP(G7,PARAM!P:Q,2,0),"*"),"") -> *1146* | K7: =CONCATENATE(C7," ",D7," ",E7,IF(G7="-","",CONCATENATE(" TALLA ",G7))) -> JEANS DAMA 4 BOTONES TALLA 16
A8: 46186 | B8: ROPA DAMA | C8: JEANS | D8: DAMA | E8: 4 BOTONES SIN BOLSILLO | F8: GRIS | G8: 16 | H8: R TREIK | I8: =IFERROR(CONCATENATE(VLOOKUP(C8,PARAM!D:E,2,0),VLOOKUP(D8,PARAM!J:K,2,0),VLOOKUP(E8,PARAM!G:H,2,0),VLOOKUP(G8,PARAM!P:Q,2,0)),"") -> 1156 | J8: =IFERROR(CONCATENATE("*",VLOOKUP(C8,PARAM!D:E,2,0),VLOOKUP(D8,PARAM!J:K,2,0),VLOOKUP(E8,PARAM!G:H,2,0),VLOOKUP(G8,PARAM!P:Q,2,0),"*"),"") -> *1156* | K8: =CONCATENATE(C8," ",D8," ",E8,IF(G8="-","",CONCATENATE(" TALLA ",G8))) -> JEANS DAMA 4 BOTONES SIN BOLSILLO TALLA 16
A9: 46186 | B9: ROPA DAMA | C9: JEANS | D9: DAMA | E9: 1 BOTON | F9: GRIS | G9: 12 | H9: R TREIK | I9: =IFERROR(CONCATENATE(VLOOKUP(C9,PARAM!D:E,2,0),VLOOKUP(D9,PARAM!J:K,2,0),VLOOKUP(E9,PARAM!G:H,2,0),VLOOKUP(G9,PARAM!P:Q,2,0)),"") -> 1114 | J9: =IFERROR(CONCATENATE("*",VLOOKUP(C9,PARAM!D:E,2,0),VLOOKUP(D9,PARAM!J:K,2,0),VLOOKUP(E9,PARAM!G:H,2,0),VLOOKUP(G9,PARAM!P:Q,2,0),"*"),"") -> *1114* | K9: =CONCATENATE(C9," ",D9," ",E9,IF(G9="-","",CONCATENATE(" TALLA ",G9))) -> JEANS DAMA 1 BOTON TALLA 12
A10: 46186 | B10: ROPA DAMA | C10: JEANS | D10: DAMA | E10: 4 BOTONES | F10: GRIS | G10: 14 | H10: R TREIK | I10: =IFERROR(CONCATENATE(VLOOKUP(C10,PARAM!D:E,2,0),VLOOKUP(D10,PARAM!J:K,2,0),VLOOKUP(E10,PARAM!G:H,2,0),VLOOKUP(G10,PARAM!P:Q,2,0)),"") -> 1145 | J10: =IFERROR(CONCATENATE("*",VLOOKUP(C10,PARAM!D:E,2,0),VLOOKUP(D10,PARAM!J:K,2,0),VLOOKUP(E10,PARAM!G:H,2,0),VLOOKUP(G10,PARAM!P:Q,2,0),"*"),"") -> *1145* | K10: =CONCATENATE(C10," ",D10," ",E10,IF(G10="-","",CONCATENATE(" TALLA ",G10))) -> JEANS DAMA 4 BOTONES TALLA 14
A11: 46186 | B11: ROPA DAMA | C11: JEANS | D11: DAMA | E11: 1 BOTON BOTA RECTA | F11: NEGRO | G11: 14 | H11: R TREIK | I11: =IFERROR(CONCATENATE(VLOOKUP(C11,PARAM!D:E,2,0),VLOOKUP(D11,PARAM!J:K,2,0),VLOOKUP(E11,PARAM!G:H,2,0),VLOOKUP(G11,PARAM!P:Q,2,0)),"") -> 1125 | J11: =IFERROR(CONCATENATE("*",VLOOKUP(C11,PARAM!D:E,2,0),VLOOKUP(D11,PARAM!J:K,2,0),VLOOKUP(E11,PARAM!G:H,2,0),VLOOKUP(G11,PARAM!P:Q,2,0),"*"),"") -> *1125* | K11: =CONCATENATE(C11," ",D11," ",E11,IF(G11="-","",CONCATENATE(" TALLA ",G11))) -> JEANS DAMA 1 BOTON BOTA RECTA TALLA 14
A12: 46186 | B12: ROPA DAMA | C12: JEANS | D12: DAMA | E12: 1 BOTON BOTA RECTA | F12: NEGRO | G12: 10 | H12: R TREIK | I12: =IFERROR(CONCATENATE(VLOOKUP(C12,PARAM!D:E,2,0),VLOOKUP(D12,PARAM!J:K,2,0),VLOOKUP(E12,PARAM!G:H,2,0),VLOOKUP(G12,PARAM!P:Q,2,0)),"") -> 1123 | J12: =IFERROR(CONCATENATE("*",VLOOKUP(C12,PARAM!D:E,2,0),VLOOKUP(D12,PARAM!J:K,2,0),VLOOKUP(E12,PARAM!G:H,2,0),VLOOKUP(G12,PARAM!P:Q,2,0),"*"),"") -> *1123* | K12: =CONCATENATE(C12," ",D12," ",E12,IF(G12="-","",CONCATENATE(" TALLA ",G12))) -> JEANS DAMA 1 BOTON BOTA RECTA TALLA 10
A13: 46186 | B13: ROPA DAMA | C13: JEANS | D13: DAMA | E13: 1 BOTON BOTA RECTA | F13: NEGRO | G13: 8 | H13: R TREIK | I13: =IFERROR(CONCATENATE(VLOOKUP(C13,PARAM!D:E,2,0),VLOOKUP(D13,PARAM!J:K,2,0),VLOOKUP(E13,PARAM!G:H,2,0),VLOOKUP(G13,PARAM!P:Q,2,0)),"") -> 1122 | J13: =IFERROR(CONCATENATE("*",VLOOKUP(C13,PARAM!D:E,2,0),VLOOKUP(D13,PARAM!J:K,2,0),VLOOKUP(E13,PARAM!G:H,2,0),VLOOKUP(G13,PARAM!P:Q,2,0),"*"),"") -> *1122* | K13: =CONCATENATE(C13," ",D13," ",E13,IF(G13="-","",CONCATENATE(" TALLA ",G13))) -> JEANS DAMA 1 BOTON BOTA RECTA TALLA 8
A14: 46186 | B14: ROPA DAMA | C14: JEANS | D14: DAMA | E14: 1 BOTON BOTA RECTA | F14: NEGRO | G14: 14 | H14: R TREIK | I14: =IFERROR(CONCATENATE(VLOOKUP(C14,PARAM!D:E,2,0),VLOOKUP(D14,PARAM!J:K,2,0),VLOOKUP(E14,PARAM!G:H,2,0),VLOOKUP(G14,PARAM!P:Q,2,0)),"") -> 1125 | J14: =IFERROR(CONCATENATE("*",VLOOKUP(C14,PARAM!D:E,2,0),VLOOKUP(D14,PARAM!J:K,2,0),VLOOKUP(E14,PARAM!G:H,2,0),VLOOKUP(G14,PARAM!P:Q,2,0),"*"),"") -> *1125* | K14: =CONCATENATE(C14," ",D14," ",E14,IF(G14="-","",CONCATENATE(" TALLA ",G14))) -> JEANS DAMA 1 BOTON BOTA RECTA TALLA 14
A15: 46186 | B15: ROPA DAMA | C15: JEANS | D15: DAMA | E15: 4 BOTONES SIN BOLSILLO | F15: NEGRO | G15: 14 | H15: R TREIK | I15: =IFERROR(CONCATENATE(VLOOKUP(C15,PARAM!D:E,2,0),VLOOKUP(D15,PARAM!J:K,2,0),VLOOKUP(E15,PARAM!G:H,2,0),VLOOKUP(G15,PARAM!P:Q,2,0)),"") -> 1155 | J15: =IFERROR(CONCATENATE("*",VLOOKUP(C15,PARAM!D:E,2,0),VLOOKUP(D15,PARAM!J:K,2,0),VLOOKUP(E15,PARAM!G:H,2,0),VLOOKUP(G15,PARAM!P:Q,2,0),"*"),"") -> *1155* | K15: =CONCATENATE(C15," ",D15," ",E15,IF(G15="-","",CONCATENATE(" TALLA ",G15))) -> JEANS DAMA 4 BOTONES SIN BOLSILLO TALLA 14
... A21: 46186 | B21: ROPA DAMA | C21: JEANS | D21: DAMA | E21: 4 BOTONES SIN BOLSILLO | F21: AZUL | G21: 8 | H21: R TREIK | I21: =IFERROR(CONCATENATE(VLOOKUP(C21,PARAM!D:E,2,0),VLOOKUP(D21,PARAM!J:K,2,0),VLOOKUP(E21,PARAM!G:H,2,0),VLOOKUP(G21,PARAM!P:Q,2,0)),"") -> 1152 | J21: =IFERROR(CONCATENATE("*",VLOOKUP(C21,PARAM!D:E,2,0),VLOOKUP(D21,PARAM!J:K,2,0),VLOOKUP(E21,PARAM!G:H,2,0),VLOOKUP(G21,PARAM!P:Q,2,0),"*"),"") -> *1152* | K21: =CONCATENATE(C21," ",D21," ",E21,IF(G21="-","",CONCATENATE(" TALLA ",G21))) -> JEANS DAMA 4 BOTONES SIN BOLSILLO TALLA 8
A22: 46186 | B22: ROPA DAMA | C22: BLUSAS | D22: DAMA | E22: BASICA ALGODON | F22: VARIOS | G22: VA | H22: LUZMAR | I22: =IFERROR(CONCATENATE(VLOOKUP(C22,PARAM!D:E,2,0),VLOOKUP(D22,PARAM!J:K,2,0),VLOOKUP(E22,PARAM!G:H,2,0),VLOOKUP(G22,PARAM!P:Q,2,0)),"") -> 614531 | J22: =IFERROR(CONCATENATE("*",VLOOKUP(C22,PARAM!D:E,2,0),VLOOKUP(D22,PARAM!J:K,2,0),VLOOKUP(E22,PARAM!G:H,2,0),VLOOKUP(G22,PARAM!P:Q,2,0),"*"),"") -> *614531* | K22: =CONCATENATE(C22," ",D22," ",E22,IF(G22="-","",CONCATENATE(" TALLA ",G22))) -> BLUSAS DAMA BASICA ALGODON TALLA VA
A23: 46186 | B23: LICRA DEPORTIVA | C23: BICICLETERO | D23: DAMA | E23: ALGODON | F23: VARIOS | G23: M-L | H23: LUZMAR | I23: =IFERROR(CONCATENATE(VLOOKUP(C23,PARAM!D:E,2,0),VLOOKUP(D23,PARAM!J:K,2,0),VLOOKUP(E23,PARAM!G:H,2,0),VLOOKUP(G23,PARAM!P:Q,2,0)),"") -> 4311626 | J23: =IFERROR(CONCATENATE("*",VLOOKUP(C23,PARAM!D:E,2,0),VLOOKUP(D23,PARAM!J:K,2,0),VLOOKUP(E23,PARAM!G:H,2,0),VLOOKUP(G23,PARAM!P:Q,2,0),"*"),"") -> *4311626* | K23: =CONCATENATE(C23," ",D23," ",E23,IF(G23="-","",CONCATENATE(" TALLA ",G23))) -> BICICLETERO DAMA ALGODON TALLA M-L
A24: 46186 | B24: LICRA DEPORTIVA | C24: BICICLETERO | D24: DAMA | E24: ALGODON | F24: VARIOS | G24: 16-S | H24: LUZMAR | I24: =IFERROR(CONCATENATE(VLOOKUP(C24,PARAM!D:E,2,0),VLOOKUP(D24,PARAM!J:K,2,0),VLOOKUP(E24,PARAM!G:H,2,0),VLOOKUP(G24,PARAM!P:Q,2,0)),"") -> 4311618 | J24: =IFERROR(CONCATENATE("*",VLOOKUP(C24,PARAM!D:E,2,0),VLOOKUP(D24,PARAM!J:K,2,0),VLOOKUP(E24,PARAM!G:H,2,0),VLOOKUP(G24,PARAM!P:Q,2,0),"*"),"") -> *4311618* | K24: =CONCATENATE(C24," ",D24," ",E24,IF(G24="-","",CONCATENATE(" TALLA ",G24))) -> BICICLETERO DAMA ALGODON TALLA 16-S
A25: 46186 | B25: LICRA DEPORTIVA | C25: BICICLETERO | D25: DAMA | E25: ALGODON | F25: VARIOS | G25: 14 | H25: LUZMAR | I25: =IFERROR(CONCATENATE(VLOOKUP(C25,PARAM!D:E,2,0),VLOOKUP(D25,PARAM!J:K,2,0),VLOOKUP(E25,PARAM!G:H,2,0),VLOOKUP(G25,PARAM!P:Q,2,0)),"") -> 431165 | J25: =IFERROR(CONCATENATE("*",VLOOKUP(C25,PARAM!D:E,2,0),VLOOKUP(D25,PARAM!J:K,2,0),VLOOKUP(E25,PARAM!G:H,2,0),VLOOKUP(G25,PARAM!P:Q,2,0),"*"),"") -> *431165* | K25: =CONCATENATE(C25," ",D25," ",E25,IF(G25="-","",CONCATENATE(" TALLA ",G25))) -> BICICLETERO DAMA ALGODON TALLA 14
A26: 46186 | B26: LICRA DEPORTIVA | C26: LEGGINS | D26: DAMA | E26: ALGODON | F26: VARIOS | G26: XL | H26: LUZMAR | I26: =IFERROR(CONCATENATE(VLOOKUP(C26,PARAM!D:E,2,0),VLOOKUP(D26,PARAM!J:K,2,0),VLOOKUP(E26,PARAM!G:H,2,0),VLOOKUP(G26,PARAM!P:Q,2,0)),"") -> 4411632 | J26: =IFERROR(CONCATENATE("*",VLOOKUP(C26,PARAM!D:E,2,0),VLOOKUP(D26,PARAM!J:K,2,0),VLOOKUP(E26,PARAM!G:H,2,0),VLOOKUP(G26,PARAM!P:Q,2,0),"*"),"") -> *4411632* | K26: =CONCATENATE(C26," ",D26," ",E26,IF(G26="-","",CONCATENATE(" TALLA ",G26))) -> LEGGINS DAMA ALGODON TALLA XL
A27: 46186 | B27: ROPA CABALLERO | C27: BERMUDAS | D27: CABALLERO | E27: CAMUFLADO | F27: BEIGE | G27: 36 | H27: GOLDTEX | I27: =IFERROR(CONCATENATE(VLOOKUP(C27,PARAM!D:E,2,0),VLOOKUP(D27,PARAM!J:K,2,0),VLOOKUP(E27,PARAM!G:H,2,0),VLOOKUP(G27,PARAM!P:Q,2,0)),"") -> 526616 | J27: =IFERROR(CONCATENATE("*",VLOOKUP(C27,PARAM!D:E,2,0),VLOOKUP(D27,PARAM!J:K,2,0),VLOOKUP(E27,PARAM!G:H,2,0),VLOOKUP(G27,PARAM!P:Q,2,0),"*"),"") -> *526616* | K27: =CONCATENATE(C27," ",D27," ",E27,IF(G27="-","",CONCATENATE(" TALLA ",G27))) -> BERMUDAS CABALLERO CAMUFLADO TALLA 36
A28: 46186 | B28: ROPA CABALLERO | C28: BERMUDAS | D28: CABALLERO | E28: CAMUFLADO | F28: CAQUI OSCURO | G28: 28 | H28: GOLDTEX | I28: =IFERROR(CONCATENATE(VLOOKUP(C28,PARAM!D:E,2,0),VLOOKUP(D28,PARAM!J:K,2,0),VLOOKUP(E28,PARAM!G:H,2,0),VLOOKUP(G28,PARAM!P:Q,2,0)),"") -> 526612 | J28: =IFERROR(CONCATENATE("*",VLOOKUP(C28,PARAM!D:E,2,0),VLOOKUP(D28,PARAM!J:K,2,0),VLOOKUP(E28,PARAM!G:H,2,0),VLOOKUP(G28,PARAM!P:Q,2,0),"*"),"") -> *526612* | K28: =CONCATENATE(C28," ",D28," ",E28,IF(G28="-","",CONCATENATE(" TALLA ",G28))) -> BERMUDAS CABALLERO CAMUFLADO TALLA 28
A29: 46186 | B29: ROPA CABALLERO | C29: BERMUDAS | D29: CABALLERO | E29: CAMUFLADO | F29: AZUL NOCHE | G29: 30 | H29: GOLDTEX | I29: =IFERROR(CONCATENATE(VLOOKUP(C29,PARAM!D:E,2,0),VLOOKUP(D29,PARAM!J:K,2,0),VLOOKUP(E29,PARAM!G:H,2,0),VLOOKUP(G29,PARAM!P:Q,2,0)),"") -> 526613 | J29: =IFERROR(CONCATENATE("*",VLOOKUP(C29,PARAM!D:E,2,0),VLOOKUP(D29,PARAM!J:K,2,0),VLOOKUP(E29,PARAM!G:H,2,0),VLOOKUP(G29,PARAM!P:Q,2,0),"*"),"") -> *526613* | K29: =CONCATENATE(C29," ",D29," ",E29,IF(G29="-","",CONCATENATE(" TALLA ",G29))) -> BERMUDAS CABALLERO CAMUFLADO TALLA 30
A30: 46186 | B30: ROPA CABALLERO | C30: BERMUDAS | D30: CABALLERO | E30: CAMUFLADO | F30: VERDE | G30: 32 | H30: GOLDTEX | I30: =IFERROR(CONCATENATE(VLOOKUP(C30,PARAM!D:E,2,0),VLOOKUP(D30,PARAM!J:K,2,0),VLOOKUP(E30,PARAM!G:H,2,0),VLOOKUP(G30,PARAM!P:Q,2,0)),"") -> 526614 | J30: =IFERROR(CONCATENATE("*",VLOOKUP(C30,PARAM!D:E,2,0),VLOOKUP(D30,PARAM!J:K,2,0),VLOOKUP(E30,PARAM!G:H,2,0),VLOOKUP(G30,PARAM!P:Q,2,0),"*"),"") -> *526614* | K30: =CONCATENATE(C30," ",D30," ",E30,IF(G30="-","",CONCATENATE(" TALLA ",G30))) -> BERMUDAS CABALLERO CAMUFLADO TALLA 32
A31: 46186 | B31: ROPA CABALLERO | C31: BERMUDAS | D31: CABALLERO | E31: CAMUFLADO | F31: NEGRO | G31: 34 | H31: GOLDTEX | I31: =IFERROR(CONCATENATE(VLOOKUP(C31,PARAM!D:E,2,0),VLOOKUP(D31,PARAM!J:K,2,0),VLOOKUP(E31,PARAM!G:H,2,0),VLOOKUP(G31,PARAM!P:Q,2,0)),"") -> 526615 | J31: =IFERROR(CONCATENATE("*",VLOOKUP(C31,PARAM!D:E,2,0),VLOOKUP(D31,PARAM!J:K,2,0),VLOOKUP(E31,PARAM!G:H,2,0),VLOOKUP(G31,PARAM!P:Q,2,0),"*"),"") -> *526615* | K31: =CONCATENATE(C31," ",D31," ",E31,IF(G31="-","",CONCATENATE(" TALLA ",G31))) -> BERMUDAS CABALLERO CAMUFLADO TALLA 34
A32: 46186 | B32: ROPA CABALLERO | C32: BERMUDAS | D32: CABALLERO | E32: CLASICA DRILL | F32: NEGRO | G32: 34 | H32: GOLDTEX | I32: =IFERROR(CONCATENATE(VLOOKUP(C32,PARAM!D:E,2,0),VLOOKUP(D32,PARAM!J:K,2,0),VLOOKUP(E32,PARAM!G:H,2,0),VLOOKUP(G32,PARAM!P:Q,2,0)),"") -> 527515 | J32: =IFERROR(CONCATENATE("*",VLOOKUP(C32,PARAM!D:E,2,0),VLOOKUP(D32,PARAM!J:K,2,0),VLOOKUP(E32,PARAM!G:H,2,0),VLOOKUP(G32,PARAM!P:Q,2,0),"*"),"") -> *527515* | K32: =CONCATENATE(C32," ",D32," ",E32,IF(G32="-","",CONCATENATE(" TALLA ",G32))) -> BERMUDAS CABALLERO CLASICA DRILL TALLA 34
A33: 46186 | B33: ROPA CABALLERO | C33: BERMUDAS | D33: CABALLERO | E33: CLASICA DRILL | F33: CAQUI OSCURO | G33: 28 | H33: GOLDTEX | I33: =IFERROR(CONCATENATE(VLOOKUP(C33,PARAM!D:E,2,0),VLOOKUP(D33,PARAM!J:K,2,0),VLOOKUP(E33,PARAM!G:H,2,0),VLOOKUP(G33,PARAM!P:Q,2,0)),"") -> 527512 | J33: =IFERROR(CONCATENATE("*",VLOOKUP(C33,PARAM!D:E,2,0),VLOOKUP(D33,PARAM!J:K,2,0),VLOOKUP(E33,PARAM!G:H,2,0),VLOOKUP(G33,PARAM!P:Q,2,0),"*"),"") -> *527512* | K33: =CONCATENATE(C33," ",D33," ",E33,IF(G33="-","",CONCATENATE(" TALLA ",G33))) -> BERMUDAS CABALLERO CLASICA DRILL TALLA 28
A34: 46186 | B34: ROPA CABALLERO | C34: BERMUDAS | D34: CABALLERO | E34: CLASICA DRILL | F34: AZUL CLARO | G34: 32 | H34: GOLDTEX | I34: =IFERROR(CONCATENATE(VLOOKUP(C34,PARAM!D:E,2,0),VLOOKUP(D34,PARAM!J:K,2,0),VLOOKUP(E34,PARAM!G:H,2,0),VLOOKUP(G34,PARAM!P:Q,2,0)),"") -> 527514 | J34: =IFERROR(CONCATENATE("*",VLOOKUP(C34,PARAM!D:E,2,0),VLOOKUP(D34,PARAM!J:K,2,0),VLOOKUP(E34,PARAM!G:H,2,0),VLOOKUP(G34,PARAM!P:Q,2,0),"*"),"") -> *527514* | K34: =CONCATENATE(C34," ",D34," ",E34,IF(G34="-","",CONCATENATE(" TALLA ",G34))) -> BERMUDAS CABALLERO CLASICA DRILL TALLA 32
A35: 46186 | B35: ROPA CABALLERO | C35: BERMUDAS | D35: CABALLERO | E35: CLASICA DRILL | F35: VERDE OSCURO | G35: 30 | H35: GOLDTEX | I35: =IFERROR(CONCATENATE(VLOOKUP(C35,PARAM!D:E,2,0),VLOOKUP(D35,PARAM!J:K,2,0),VLOOKUP(E35,PARAM!G:H,2,0),VLOOKUP(G35,PARAM!P:Q,2,0)),"") -> 527513 | J35: =IFERROR(CONCATENATE("*",VLOOKUP(C35,PARAM!D:E,2,0),VLOOKUP(D35,PARAM!J:K,2,0),VLOOKUP(E35,PARAM!G:H,2,0),VLOOKUP(G35,PARAM!P:Q,2,0),"*"),"") -> *527513* | K35: =CONCATENATE(C35," ",D35," ",E35,IF(G35="-","",CONCATENATE(" TALLA ",G35))) -> BERMUDAS CABALLERO CLASICA DRILL TALLA 30
A36: 46186 | B36: ROPA DAMA | C36: SHORTS | D36: DAMA | E36: SHORT ARO | F36: VARIOS | G36: VA | H36: GOLDTEX | I36: =IFERROR(CONCATENATE(VLOOKUP(C36,PARAM!D:E,2,0),VLOOKUP(D36,PARAM!J:K,2,0),VLOOKUP(E36,PARAM!G:H,2,0),VLOOKUP(G36,PARAM!P:Q,2,0)),"") -> 4125131 | J36: =IFERROR(CONCATENATE("*",VLOOKUP(C36,PARAM!D:E,2,0),VLOOKUP(D36,PARAM!J:K,2,0),VLOOKUP(E36,PARAM!G:H,2,0),VLOOKUP(G36,PARAM!P:Q,2,0),"*"),"") -> *4125131* | K36: =CONCATENATE(C36," ",D36," ",E36,IF(G36="-","",CONCATENATE(" TALLA ",G36))) -> SHORTS DAMA SHORT ARO TALLA VA
A37: 46186 | B37: ROPA DAMA | C37: SHORTS | D37: DAMA | E37: CINTURON ANCHO | F37: VARIOS | G37: VA | H37: GOLDTEX | I37: =IFERROR(CONCATENATE(VLOOKUP(C37,PARAM!D:E,2,0),VLOOKUP(D37,PARAM!J:K,2,0),VLOOKUP(E37,PARAM!G:H,2,0),VLOOKUP(G37,PARAM!P:Q,2,0)),"") -> 417431 | J37: =IFERROR(CONCATENATE("*",VLOOKUP(C37,PARAM!D:E,2,0),VLOOKUP(D37,PARAM!J:K,2,0),VLOOKUP(E37,PARAM!G:H,2,0),VLOOKUP(G37,PARAM!P:Q,2,0),"*"),"") -> *417431* | K37: =CONCATENATE(C37," ",D37," ",E37,IF(G37="-","",CONCATENATE(" TALLA ",G37))) -> SHORTS DAMA CINTURON ANCHO TALLA VA
A38: 46186 | B38: ROPA DAMA | C38: BERMUDAS | D38: DAMA | E38: DRILL | F38: VARIOS | G38: VA | H38: GOLDTEX | I38: =IFERROR(CONCATENATE(VLOOKUP(C38,PARAM!D:E,2,0),VLOOKUP(D38,PARAM!J:K,2,0),VLOOKUP(E38,PARAM!G:H,2,0),VLOOKUP(G38,PARAM!P:Q,2,0)),"") -> 5112131 | J38: =IFERROR(CONCATENATE("*",VLOOKUP(C38,PARAM!D:E,2,0),VLOOKUP(D38,PARAM!J:K,2,0),VLOOKUP(E38,PARAM!G:H,2,0),VLOOKUP(G38,PARAM!P:Q,2,0),"*"),"") -> *5112131* | K38: =CONCATENATE(C38," ",D38," ",E38,IF(G38="-","",CONCATENATE(" TALLA ",G38))) -> BERMUDAS DAMA DRILL TALLA VA
A39: 46186 | B39: PERFUMERIA | C39: PERFUMES | D39: DAMA | E39: PINK MINI | F39: VARIOS | G39: - | I39: =IFERROR(CONCATENATE(VLOOKUP(C39,PARAM!D:E,2,0),VLOOKUP(D39,PARAM!J:K,2,0),VLOOKUP(E39,PARAM!G:H,2,0),VLOOKUP(G39,PARAM!P:Q,2,0)),"") -> 1212110 | J39: =IFERROR(CONCATENATE("*",VLOOKUP(C39,PARAM!D:E,2,0),VLOOKUP(D39,PARAM!J:K,2,0),VLOOKUP(E39,PARAM!G:H,2,0),VLOOKUP(G39,PARAM!P:Q,2,0),"*"),"") -> *1212110* | K39: =CONCATENATE(C39," ",D39," ",E39,IF(G39="-","",CONCATENATE(" TALLA ",G39))) -> PERFUMES DAMA PINK MINI
A40: 46186 | B40: MAQUILLAJE | C40: BRILLO | D40: DAMA | E40: LABIAL | F40: VARIOS | G40: - | I40: =IFERROR(CONCATENATE(VLOOKUP(C40,PARAM!D:E,2,0),VLOOKUP(D40,PARAM!J:K,2,0),VLOOKUP(E40,PARAM!G:H,2,0),VLOOKUP(G40,PARAM!P:Q,2,0)),"") -> 4711600 | J40: =IFERROR(CONCATENATE("*",VLOOKUP(C40,PARAM!D:E,2,0),VLOOKUP(D40,PARAM!J:K,2,0),VLOOKUP(E40,PARAM!G:H,2,0),VLOOKUP(G40,PARAM!P:Q,2,0),"*"),"") -> *4711600* | K40: =CONCATENATE(C40," ",D40," ",E40,IF(G40="-","",CONCATENATE(" TALLA ",G40))) -> BRILLO DAMA LABIAL
